I'm sorry, but an uncaught exception occurred.

While running game code:
  File "game/script.rpy", line 48, in script
    e "You've created a new Ren'Py game."
Exception: Sayer 'e' is not defined.

-- Full Traceback ------------------------------------------------------------

Full traceback:
  File "game/script.rpy", line 48, in script
    e "You've created a new Ren'Py game."
  File "/Users/kids/Desktop/renpy-8.3.7-sdk/renpy/ast.py", line 2586, in execute
    Say.execute(self)
  File "/Users/kids/Desktop/renpy-8.3.7-sdk/renpy/ast.py", line 583, in execute
    who = eval_who(self.who, self.who_fast)
  File "/Users/kids/Desktop/renpy-8.3.7-sdk/renpy/ast.py", line 472, in eval_who
    raise Exception("Sayer '%s' is not defined." % who)
Exception: Sayer 'e' is not defined.

macOS-10.16-x86_64-i386-64bit x86_64
Ren'Py 8.3.7.25031702
no right answer 1.0
Sat Sep 27 12:18:46 2025
